<?xml version="1.0" ?>
<!-- =================================================================================== -->
<!-- |    This document was autogenerated by xacro from /opt/ros/noetic/share/ridgeback_description/urdf/ridgeback.urdf.xacro | -->
<!-- |    EDITING THIS FILE BY HAND IS NOT RECOMMENDED                                 | -->
<!-- =================================================================================== -->
<robot name="ridgeback">
    <material name="dark_grey">
        <color rgba="0.2 0.2 0.2 1.0" />
    </material>
    <material name="light_grey">
        <color rgba="0.4 0.4 0.4 1.0" />
    </material>
    <material name="red">
        <color rgba="0.8 0.0 0.0 1.0" />
    </material>
    <material name="white">
        <color rgba="0.9 0.9 0.9 1.0" />
    </material>
    <material name="yellow">
        <color rgba="0.8 0.8 0.0 1.0" />
    </material>
    <material name="black">
        <color rgba="0.15 0.15 0.15 1.0" />
    </material>
    <link name="front_rocker_link">
        <visual>
            <origin rpy="1.5707963267948966 0 1.5707963267948966" xyz="0 0 0" />
            <geometry>
                <mesh filename="package://ridgeback_description/meshes/rocker.stl" />
            </geometry>
            <material name="black" />
        </visual>
        <inertial>
            <origin rpy="1.5707963267948966 0 1.5707963267948966" xyz="0 0 0" />
            <mass value="10.267" />
            <inertia ixx="0.0288" ixy="2.20484e-6" ixz="-1.3145e-5" iyy="0.4324" iyz="1.8944e-3" izz="0.4130" />
        </inertial>
    </link>
    <joint name="front_rocker" type="revolute">
        <parent link="axle_link" />
        <child link="front_rocker_link" />
        <origin rpy="0 0 0" xyz="0.319 0 0" />
        <axis xyz="1 0 0" />
        <limit effort="0" lower="-0.08726" upper="0.08726" velocity="0" />
    </joint>
    <link name="front_left_wheel_link">
        <visual>
            <origin rpy="1.5707963267948966 0 0" xyz="0 0 0" />
            <geometry>
                <mesh filename="package://ridgeback_description/meshes/wheel.stl" />
            </geometry>
            <material name="black" />
        </visual>
        <collision>
            <origin rpy="1.5707963267948966 0 0" xyz="0 0 0" />
            <geometry>
                <cylinder length="0.079" radius="0.0759" />
            </geometry>
        </collision>
        <inertial>
            <origin rpy="0 0 0" xyz="0 0 0" />
            <mass value="2.3" />
            <inertia ixx="3.3212e-3" ixy="0" ixz="0" iyy="6.6424e-3" iyz="0" izz="3.3212e-3" />
        </inertial>
    </link>
    <joint name="front_left_wheel" type="continuous">
        <parent link="front_rocker_link" />
        <child link="front_left_wheel_link" />
        <origin rpy="0 0 0" xyz="0 0.27549999999999997 0" />
        <axis xyz="0 1 0" />
    </joint>
    <transmission name="front_wheel_trans">
        <type>transmission_interface/SimpleTransmission</type>
        <joint name="front_left_wheel">
            <hardwareInterface>hardware_interface/VelocityJointInterface</hardwareInterface>
        </joint>
        <actuator name="front_left_actuator">
            <mechanicalReduction>1</mechanicalReduction>
            <hardwareInterface>hardware_interface/EffortJointInterface</hardwareInterface>
        </actuator>
    </transmission>
    <link name="front_right_wheel_link">
        <visual>
            <origin rpy="1.5707963267948966 0 0" xyz="0 0 0" />
            <geometry>
                <mesh filename="package://ridgeback_description/meshes/wheel.stl" />
            </geometry>
            <material name="black" />
        </visual>
        <collision>
            <origin rpy="1.5707963267948966 0 0" xyz="0 0 0" />
            <geometry>
                <cylinder length="0.079" radius="0.0759" />
            </geometry>
        </collision>
        <inertial>
            <origin rpy="0 0 0" xyz="0 0 0" />
            <mass value="2.3" />
            <inertia ixx="3.3212e-3" ixy="0" ixz="0" iyy="6.6424e-3" iyz="0" izz="3.3212e-3" />
        </inertial>
    </link>
    <joint name="front_right_wheel" type="continuous">
        <parent link="front_rocker_link" />
        <child link="front_right_wheel_link" />
        <origin rpy="0 0 0" xyz="0 -0.27549999999999997 0" />
        <axis xyz="0 1 0" />
    </joint>
    <transmission name="front_wheel_trans">
        <type>transmission_interface/SimpleTransmission</type>
        <joint name="front_right_wheel">
            <hardwareInterface>hardware_interface/VelocityJointInterface</hardwareInterface>
        </joint>
        <actuator name="front_right_actuator">
            <mechanicalReduction>1</mechanicalReduction>
            <hardwareInterface>hardware_interface/EffortJointInterface</hardwareInterface>
        </actuator>
    </transmission>
    <link name="rear_rocker_link">
        <visual>
            <origin rpy="1.5707963267948966 0 1.5707963267948966" xyz="0 0 0" />
            <geometry>
                <mesh filename="package://ridgeback_description/meshes/rocker.stl" />
            </geometry>
            <material name="black" />
        </visual>
        <inertial>
            <origin rpy="1.5707963267948966 0 1.5707963267948966" xyz="0 0 0" />
            <mass value="10.267" />
            <inertia ixx="0.0288" ixy="2.20484e-6" ixz="-1.3145e-5" iyy="0.4324" iyz="1.8944e-3" izz="0.4130" />
        </inertial>
    </link>
    <joint name="rear_rocker" type="fixed">
        <parent link="axle_link" />
        <child link="rear_rocker_link" />
        <origin rpy="0 0 0" xyz="-0.319 0 0" />
        <axis xyz="1 0 0" />
        <limit effort="0" velocity="0" />
    </joint>
    <link name="rear_left_wheel_link">
        <visual>
            <origin rpy="1.5707963267948966 0 0" xyz="0 0 0" />
            <geometry>
                <mesh filename="package://ridgeback_description/meshes/wheel.stl" />
            </geometry>
            <material name="black" />
        </visual>
        <collision>
            <origin rpy="1.5707963267948966 0 0" xyz="0 0 0" />
            <geometry>
                <cylinder length="0.079" radius="0.0759" />
            </geometry>
        </collision>
        <inertial>
            <origin rpy="0 0 0" xyz="0 0 0" />
            <mass value="2.3" />
            <inertia ixx="3.3212e-3" ixy="0" ixz="0" iyy="6.6424e-3" iyz="0" izz="3.3212e-3" />
        </inertial>
    </link>
    <joint name="rear_left_wheel" type="continuous">
        <parent link="rear_rocker_link" />
        <child link="rear_left_wheel_link" />
        <origin rpy="0 0 0" xyz="0 0.27549999999999997 0" />
        <axis xyz="0 1 0" />
    </joint>
    <transmission name="rear_wheel_trans">
        <type>transmission_interface/SimpleTransmission</type>
        <joint name="rear_left_wheel">
            <hardwareInterface>hardware_interface/VelocityJointInterface</hardwareInterface>
        </joint>
        <actuator name="rear_left_actuator">
            <mechanicalReduction>1</mechanicalReduction>
            <hardwareInterface>hardware_interface/EffortJointInterface</hardwareInterface>
        </actuator>
    </transmission>
    <link name="rear_right_wheel_link">
        <visual>
            <origin rpy="1.5707963267948966 0 0" xyz="0 0 0" />
            <geometry>
                <mesh filename="package://ridgeback_description/meshes/wheel.stl" />
            </geometry>
            <material name="black" />
        </visual>
        <collision>
            <origin rpy="1.5707963267948966 0 0" xyz="0 0 0" />
            <geometry>
                <cylinder length="0.079" radius="0.0759" />
            </geometry>
        </collision>
        <inertial>
            <origin rpy="0 0 0" xyz="0 0 0" />
            <mass value="2.3" />
            <inertia ixx="3.3212e-3" ixy="0" ixz="0" iyy="6.6424e-3" iyz="0" izz="3.3212e-3" />
        </inertial>
    </link>
    <joint name="rear_right_wheel" type="continuous">
        <parent link="rear_rocker_link" />
        <child link="rear_right_wheel_link" />
        <origin rpy="0 0 0" xyz="0 -0.27549999999999997 0" />
        <axis xyz="0 1 0" />
    </joint>
    <transmission name="rear_wheel_trans">
        <type>transmission_interface/SimpleTransmission</type>
        <joint name="rear_right_wheel">
            <hardwareInterface>hardware_interface/VelocityJointInterface</hardwareInterface>
        </joint>
        <actuator name="rear_right_actuator">
            <mechanicalReduction>1</mechanicalReduction>
            <hardwareInterface>hardware_interface/EffortJointInterface</hardwareInterface>
        </actuator>
    </transmission>
    <link name="base_link" />
    <joint name="base_link_joint" type="fixed">
        <origin rpy="0 0 0" xyz="0 0 0" />
        <parent link="base_link" />
        <child link="chassis_link" />
    </joint>
    <link name="chassis_link">
        <visual>
            <origin rpy="0 0 0" xyz="0 0 0" />
            <geometry>
                <mesh filename="package://ridgeback_description/meshes/body.stl" />
            </geometry>
            <material name="black" />
        </visual>
        <collision>
            <origin xyz="0 0 0" />
            <geometry>
                <mesh filename="package://ridgeback_description/meshes/body-collision.stl" />
            </geometry>
        </collision>
        <inertial>
            <origin rpy="1.5707963267948966 0 1.5707963267948966" xyz="0.012 0.002 0.067" />
            <mass value="165.304" />
            <inertia ixx="4.4744" ixy="0.03098" ixz="0.003647" iyy="7.1624" iyz="0.1228" izz="4.6155" />
        </inertial>
    </link>
    <link name="riser_link">
        <visual>
            <origin rpy="0 0 0.7853981633974483" xyz="0 0 0.0275" />
            <geometry>
                <box size="0.493 0.493 0.055" />
            </geometry>
            <material name="light_grey" />
        </visual>
        <collision>
            <origin rpy="0 0 0.7853981633974483" xyz="0 0 0.0275" />
            <geometry>
                <box size="0.493 0.493 0.055" />
            </geometry>
        </collision>
        <inertial>
            <mass value="0.1" />
            <origin xyz="0 0 0" rpy="0 0 0" />
            <inertia ixx="0.03" iyy="0.03" izz="0.03" ixy="0.0" ixz="0.0" iyz="0.0" />
        </inertial>
    </link>
    <joint name="riser_link_joint" type="fixed">
        <origin rpy="0 0 0" xyz="0 0 0.22" />
        <parent link="chassis_link" />
        <child link="riser_link" />
    </joint>
    <joint name="right_side_cover_link_joint" type="fixed">
        <origin rpy="0 0 0" xyz="0 0 0" />
        <parent link="chassis_link" />
        <child link="right_side_cover_link" />
    </joint>
    <joint name="left_side_cover_link_joint" type="fixed">
        <origin rpy="0 0 0" xyz="0 0 0" />
        <parent link="chassis_link" />
        <child link="left_side_cover_link" />
    </joint>
    <link name="left_side_cover_link">
        <visual>
            <origin rpy="0 0 3.141592653589793" xyz="0 0 0" />
            <geometry>
                <mesh filename="package://ridgeback_description/meshes/side-cover.stl" />
            </geometry>
            <material name="yellow" />
        </visual>
    </link>
    <link name="right_side_cover_link">
        <visual>
            <origin rpy="0 0 0" xyz="0 0 0" />
            <geometry>
                <mesh filename="package://ridgeback_description/meshes/side-cover.stl" />
            </geometry>
            <material name="yellow" />
        </visual>
    </link>
    <joint name="front_cover_link_joint" type="fixed">
        <origin rpy="0 0 0" xyz="0 0 0" />
        <parent link="chassis_link" />
        <child link="front_cover_link" />
    </joint>
    <link name="front_cover_link">
        <visual>
            <origin rpy="0 0 0" xyz="0 0 0" />
            <geometry>
                <mesh filename="package://ridgeback_description/meshes/end-cover.stl" />
            </geometry>
            <material name="black" />
        </visual>
    </link>
    <joint name="rear_cover_link_joint" type="fixed">
        <origin rpy="0 0 0" xyz="0 0 0" />
        <parent link="chassis_link" />
        <child link="rear_cover_link" />
    </joint>
    <link name="rear_cover_link">
        <visual>
            <origin rpy="0 0 3.141592653589793" xyz="0 0 0" />
            <geometry>
                <mesh filename="package://ridgeback_description/meshes/end-cover.stl" />
            </geometry>
            <material name="black" />
        </visual>
    </link>
    <joint name="front_lights_link_joint" type="fixed">
        <origin rpy="0 0 0" xyz="0 0 0" />
        <parent link="chassis_link" />
        <child link="front_lights_link" />
    </joint>
    <joint name="rear_lights_link_joint" type="fixed">
        <origin rpy="0 0 0" xyz="0 0 0" />
        <parent link="chassis_link" />
        <child link="rear_lights_link" />
    </joint>
    <link name="front_lights_link">
        <visual>
            <origin rpy="0 0 0" xyz="0 0 0" />
            <geometry>
                <mesh filename="package://ridgeback_description/meshes/lights.stl" />
            </geometry>
            <material name="white" />
        </visual>
    </link>
    <link name="rear_lights_link">
        <visual>
            <origin rpy="0 0 3.141592653589793" xyz="0 0 0" />
            <geometry>
                <mesh filename="package://ridgeback_description/meshes/lights.stl" />
            </geometry>
            <material name="black" />
        </visual>
    </link>
    <joint name="top_link_joint" type="fixed">
        <origin rpy="0 0 0" xyz="0 0 -0.22000000000000003" />
        <parent link="riser_link" />
        <child link="top_link" />
    </joint>
    <link name="top_link">
        <visual>
            <origin rpy="0 0 0" xyz="0 0 0" />
            <geometry>
                <mesh filename="package://ridgeback_description/meshes/top.stl" />
            </geometry>
            <material name="black" />
        </visual>
        <collision>
            <origin rpy="0 0 0" xyz="0 0 0" />
            <geometry>
                <mesh filename="package://ridgeback_description/meshes/top.stl" />
            </geometry>
        </collision>
        <inertial>
            <mass value="0.1" />
            <origin xyz="0 0 0" rpy="0 0 0" />
            <inertia ixx="0.03" iyy="0.03" izz="0.03" ixy="0.0" ixz="0.0" iyz="0.0" />
        </inertial>
    </link>
    <joint name="axle_joint" type="fixed">
        <origin rpy="0 0 0" xyz="0 0 0.05" />
        <parent link="chassis_link" />
        <child link="axle_link" />
    </joint>
    <link name="axle_link">
        <visual>
            <origin rpy="0 1.5707963267948966 0" xyz="0 0 0" />
            <geometry>
                <mesh filename="package://ridgeback_description/meshes/axle.stl" />
            </geometry>
            <material name="black" />
        </visual>
    </link>
    <link name="imu_link">
        <inertial>
            <mass value="0.001" />
            <origin rpy="0 0 0" xyz="0 0 0" />
            <inertia ixx="1e-09" ixy="0.0" ixz="0.0" iyy="1e-09" iyz="0.0" izz="1e-09" />
        </inertial>
    </link>
    <joint name="imu_joint" type="fixed">
        <parent link="chassis_link" />
        <child link="imu_link" />
        <origin rpy="0 0 0" xyz="0.2085 -0.2902 0.1681" />
    </joint>
    <link name="mid_mount" />
    <joint name="mid_mount_joint" type="fixed">
        <parent link="riser_link" />
        <child link="mid_mount" />
        <origin rpy="0 0 0" xyz="0 0 0.06" />
    </joint>
    <gazebo>
        <!--plugin name="gazebo_ros_control" filename="libgazebo_ros_control.so">
	    <robotNamespace>/ridgeback</robotNamespace>
    </plugin-->
        <plugin filename="libridgeback_ros_force_based_move.so" name="ridgeback_ros_force_based_move">
            <robotNamespace>/</robotNamespace>
            <commandTopic>cmd_vel</commandTopic>
            <odometryTopic>odom</odometryTopic>
            <odometryFrame>odom</odometryFrame>
            <odometryRate>25.0</odometryRate>
            <robotBaseFrame>base_link</robotBaseFrame>
            <cmdVelTimeOut>0.25</cmdVelTimeOut>
            <!-- Don't publish a transform: the controller does it. -->
            <publishOdometry>1</publishOdometry>
            <publishOdometryTf>1</publishOdometryTf>
            <yaw_velocity_p_gain>500.0</yaw_velocity_p_gain>
            <x_velocity_p_gain>10000.0</x_velocity_p_gain>
            <y_velocity_p_gain>10000.0</y_velocity_p_gain>
        </plugin>
        <plugin filename="libhector_gazebo_ros_imu.so" name="imu_controller">
            <robotNamespace>/</robotNamespace>
            <updateRate>50.0</updateRate>
            <bodyName>imu_link</bodyName>
            <topicName>imu/data</topicName>
            <frameId>base_link</frameId>
            <accelDrift>0.005 0.005 0.005</accelDrift>
            <accelGaussianNoise>0.005 0.005 0.005</accelGaussianNoise>
            <rateDrift>0.00005 0.00005 0.00005</rateDrift>
            <rateGaussianNoise>0.00005 0.00005 0.00005</rateGaussianNoise>
            <headingDrift>0.005</headingDrift>
            <headingGaussianNoise>0.005</headingGaussianNoise>
        </plugin>
        <plugin filename="libgazebo_ros_joint_state_publisher.so" name="gazebo_ros_joint_state_publisher">
            <jointName>front_rocker</jointName>
            <robotNamespace>/</robotNamespace>
            <updateRate>50.0</updateRate>
        </plugin>
        <plugin name="gazebo_ros_control" filename="libgazebo_ros_control.so">
            <robotNamespace>/</robotNamespace>
        </plugin>
    </gazebo>
    <!-- All static links get collapsed down to base_link in Gazebo, so that's
       the one to apply the colour to (in Gazebo 5+). -->
    <gazebo reference="base_link">
        <material>Gazebo/DarkGrey</material>
        <gravity>true</gravity>
    </gazebo>
    <!-- Individual link colouring still needed in Gazebo 2.x -->
    <gazebo reference="chassis_link">
        <material>Gazebo/DarkGrey</material>
    </gazebo>
    <gazebo reference="top_link">
        <material>Gazebo/DarkGrey</material>
    </gazebo>
    <gazebo reference="left_side_cover_link">
        <material>Gazebo/Yellow</material>
    </gazebo>
    <gazebo reference="right_side_cover_link">
        <material>Gazebo/Yellow</material>
    </gazebo>
    <gazebo reference="front_cover_link">
        <material>Gazebo/DarkGrey</material>
    </gazebo>
    <gazebo reference="rear_cover_link">
        <material>Gazebo/DarkGrey</material>
    </gazebo>
    <gazebo reference="front_lights_link">
        <material>Gazebo/White</material>
    </gazebo>
    <gazebo reference="rear_lights_link">
        <material>Gazebo/Red</material>
    </gazebo>
    <gazebo reference="front_rocker_link">
        <material>Gazebo/DarkGrey</material>
    </gazebo>
    <gazebo reference="rear_rocker_link">
        <material>Gazebo/DarkGrey</material>
    </gazebo>
    <gazebo reference="axle_link">
        <material>Gazebo/DarkGrey</material>
    </gazebo>
    <!-- Wheel friction to zero, as movement is handled by applying forces at
       the body level. -->
    <gazebo reference="front_left_wheel_link">
        <material>Gazebo/DarkGrey</material>
        <mu1>0.0</mu1>
        <mu2>0.0</mu2>
    </gazebo>
    <gazebo reference="front_right_wheel_link">
        <material>Gazebo/DarkGrey</material>
        <mu1>0.0</mu1>
        <mu2>0.0</mu2>
    </gazebo>
    <gazebo reference="rear_left_wheel_link">
        <material>Gazebo/DarkGrey</material>
        <mu1>0.0</mu1>
        <mu2>0.0</mu2>
    </gazebo>
    <gazebo reference="rear_right_wheel_link">
        <material>Gazebo/DarkGrey</material>
        <mu1>0.0</mu1>
        <mu2>0.0</mu2>
    </gazebo>
    <!-- This is an wheel-level solution to possibly revisit at a future date. -->
    <!--gazebo>
    <plugin name="mecanum_gazebo" filename="libmecanum_force_plugin.so">
      <wheelJointName>front_left_wheel</wheelJointName>
      <forceScaleFactor>1</forceScaleFactor>
    </plugin>
    <plugin name="mecanum_gazebo" filename="libmecanum_force_plugin.so">
      <wheelJointName>front_right_wheel</wheelJointName>
      <forceScaleFactor>-1</forceScaleFactor>
    </plugin>
    <plugin name="mecanum_gazebo" filename="libmecanum_force_plugin.so">
      <wheelJointName>rear_left_wheel</wheelJointName>
      <forceScaleFactor>-1</forceScaleFactor>
    </plugin>
    <plugin name="mecanum_gazebo" filename="libmecanum_force_plugin.so">
      <wheelJointName>rear_right_wheel</wheelJointName>
      <forceScaleFactor>1</forceScaleFactor>
    </plugin>
  </gazebo-->
    <!--
    As you add to this URDF, please be aware that both the robot and
    simulation include it. You must retain compatibility with all of
    the following launch files:

    ridgeback_viz/launch/view_model.launch
    ridgeback_gazebo/launch/ridgeback_world.launch
    ridgeback_base/launch/base.launch
  -->
    <!-- sub-link defining detailed meshes for collision with environment -->
    <link name="fr3_link0">
        <visual>
            <geometry>
                <mesh filename="package://franka_description/meshes/visual/link0.dae" />
            </geometry>
        </visual>
        <collision>
            <geometry>
                <mesh filename="package://franka_description/meshes/collision/link0.stl" />
            </geometry>
        </collision>
        <inertial>
            <origin rpy="0 0 0" xyz="-0.041018 -0.00014 0.049974" />
            <mass value="0.629769" />
            <inertia ixx="0.00315" ixy="8.2904e-07" ixz="0.00015" iyy="0.00388" iyz="8.2299e-06" izz="0.004285" />
        </inertial>
    </link>
    <!-- sub-link defining coarse geometries of real robot's internal self-collision -->
    <link name="fr3_link0_sc" />
    <!-- fixed joint between both sub-links -->
    <joint name="fr3_link0_sc_joint" type="fixed">
        <origin rpy="0 0 0" />
        <parent link="fr3_link0" />
        <child link="fr3_link0_sc" />
    </joint>
    <!-- sub-link defining detailed meshes for collision with environment -->
    <link name="fr3_link1">
        <visual>
            <geometry>
                <mesh filename="package://franka_description/meshes/visual/link1.dae" />
            </geometry>
        </visual>
        <collision>
            <geometry>
                <mesh filename="package://franka_description/meshes/collision/link1.stl" />
            </geometry>
        </collision>
        <inertial>
            <origin rpy="0 0 0" xyz="0.003875 0.002081 -0.04762" />
            <mass value="4.970684" />
            <inertia ixx="0.70337" ixy="-0.000139" ixz="0.006772" iyy="0.70661" iyz="0.019169" izz="0.009117" />
        </inertial>
    </link>
    <!-- sub-link defining coarse geometries of real robot's internal self-collision -->
    <link name="fr3_link1_sc" />
    <!-- fixed joint between both sub-links -->
    <joint name="fr3_link1_sc_joint" type="fixed">
        <origin rpy="0 0 0" />
        <parent link="fr3_link1" />
        <child link="fr3_link1_sc" />
    </joint>
    <joint name="fr3_joint1" type="revolute">
        <origin rpy="0 0 0" xyz="0 0 0.333" />
        <parent link="fr3_link0" />
        <child link="fr3_link1" />
        <axis xyz="0 0 1" />
        <limit effort="87.0" lower="-2.3093" upper="2.3093" velocity="2.0" />
        <safety_controller k_position="100.0" k_velocity="40.0" soft_lower_limit="-2.3093" soft_upper_limit="2.3093" />
        <dynamics D="1" K="7000" damping="0.003" friction="0.0" mu_coulomb="0" mu_viscous="16" />
    </joint>
    <!-- sub-link defining detailed meshes for collision with environment -->
    <link name="fr3_link2">
        <visual>
            <geometry>
                <mesh filename="package://franka_description/meshes/visual/link2.dae" />
            </geometry>
        </visual>
        <collision>
            <geometry>
                <mesh filename="package://franka_description/meshes/collision/link2.stl" />
            </geometry>
        </collision>
        <inertial>
            <origin rpy="0 0 0" xyz="-0.003141 -0.02872  0.003495" />
            <mass value="0.646926" />
            <inertia ixx="0.007962" ixy="-0.003925" ixz="0.010254" iyy="0.02811" iyz="0.000704" izz="0.025995" />
        </inertial>
    </link>
    <!-- sub-link defining coarse geometries of real robot's internal self-collision -->
    <link name="fr3_link2_sc" />
    <!-- fixed joint between both sub-links -->
    <joint name="fr3_link2_sc_joint" type="fixed">
        <origin rpy="0 0 0" />
        <parent link="fr3_link2" />
        <child link="fr3_link2_sc" />
    </joint>
    <joint name="fr3_joint2" type="revolute">
        <origin rpy="-1.5707963267948966 0 0" xyz="0 0 0" />
        <parent link="fr3_link1" />
        <child link="fr3_link2" />
        <axis xyz="0 0 1" />
        <limit effort="87.0" lower="-1.5133" upper="1.5133" velocity="1.0" />
        <safety_controller k_position="100.0" k_velocity="40.0" soft_lower_limit="-1.5133" soft_upper_limit="1.5133" />
        <dynamics D="1" K="7000" damping="0.003" friction="0.0" mu_coulomb="0" mu_viscous="16" />
    </joint>
    <!-- sub-link defining detailed meshes for collision with environment -->
    <link name="fr3_link3">
        <visual>
            <geometry>
                <mesh filename="package://franka_description/meshes/visual/link3.dae" />
            </geometry>
        </visual>
        <collision>
            <geometry>
                <mesh filename="package://franka_description/meshes/collision/link3.stl" />
            </geometry>
        </collision>
        <inertial>
            <origin rpy="0 0 0" xyz="2.7518e-02 3.9252e-02 -6.6502e-02" />
            <mass value="3.228604" />
            <inertia ixx="0.037242" ixy="-0.004761" ixz="-0.011396" iyy="0.036155" iyz="-0.012805" izz="0.01083" />
        </inertial>
    </link>
    <!-- sub-link defining coarse geometries of real robot's internal self-collision -->
    <link name="fr3_link3_sc" />
    <!-- fixed joint between both sub-links -->
    <joint name="fr3_link3_sc_joint" type="fixed">
        <origin rpy="0 0 0" />
        <parent link="fr3_link3" />
        <child link="fr3_link3_sc" />
    </joint>
    <joint name="fr3_joint3" type="revolute">
        <origin rpy="1.5707963267948966 0 0" xyz="0 -0.316 0" />
        <parent link="fr3_link2" />
        <child link="fr3_link3" />
        <axis xyz="0 0 1" />
        <limit effort="87.0" lower="-2.4937" upper="2.4937" velocity="1.5" />
        <safety_controller k_position="100.0" k_velocity="40.0" soft_lower_limit="-2.4937" soft_upper_limit="2.4937" />
        <dynamics D="1" K="7000" damping="0.003" friction="0.0" mu_coulomb="0" mu_viscous="16" />
    </joint>
    <!-- sub-link defining detailed meshes for collision with environment -->
    <link name="fr3_link4">
        <visual>
            <geometry>
                <mesh filename="package://franka_description/meshes/visual/link4.dae" />
            </geometry>
        </visual>
        <collision>
            <geometry>
                <mesh filename="package://franka_description/meshes/collision/link4.stl" />
            </geometry>
        </collision>
        <inertial>
            <origin rpy="0 0 0" xyz="-5.317e-02 1.04419e-01 2.7454e-02" />
            <mass value="3.587895" />
            <inertia ixx="0.025853" ixy="0.007796" ixz="-0.001332" iyy="0.019552" iyz="0.008641" izz="0.028323" />
        </inertial>
    </link>
    <!-- sub-link defining coarse geometries of real robot's internal self-collision -->
    <link name="fr3_link4_sc" />
    <!-- fixed joint between both sub-links -->
    <joint name="fr3_link4_sc_joint" type="fixed">
        <origin rpy="0 0 0" />
        <parent link="fr3_link4" />
        <child link="fr3_link4_sc" />
    </joint>
    <joint name="fr3_joint4" type="revolute">
        <origin rpy="1.5707963267948966 0 0" xyz="0.0825 0 0" />
        <parent link="fr3_link3" />
        <child link="fr3_link4" />
        <axis xyz="0 0 1" />
        <limit effort="87.0" lower="-2.7478" upper="-0.4461" velocity="1.25" />
        <safety_controller k_position="100.0" k_velocity="40.0" soft_lower_limit="-2.7478" soft_upper_limit="-0.4461" />
        <dynamics D="1" K="7000" damping="0.003" friction="0.0" mu_coulomb="0" mu_viscous="16" />
    </joint>
    <!-- sub-link defining detailed meshes for collision with environment -->
    <link name="fr3_link5">
        <visual>
            <geometry>
                <mesh filename="package://franka_description/meshes/visual/link5.dae" />
            </geometry>
        </visual>
        <collision>
            <geometry>
                <mesh filename="package://franka_description/meshes/collision/link5.stl" />
            </geometry>
        </collision>
        <inertial>
            <origin rpy="0 0 0" xyz="-1.1953e-02 4.1065e-02 -3.8437e-02" />
            <mass value="1.225946" />
            <inertia ixx="0.035549" ixy="-0.002117" ixz="-0.004037" iyy="0.029474" iyz="0.000229" izz="0.008627" />
        </inertial>
    </link>
    <!-- sub-link defining coarse geometries of real robot's internal self-collision -->
    <link name="fr3_link5_sc" />
    <!-- fixed joint between both sub-links -->
    <joint name="fr3_link5_sc_joint" type="fixed">
        <origin rpy="0 0 0" />
        <parent link="fr3_link5" />
        <child link="fr3_link5_sc" />
    </joint>
    <joint name="fr3_joint5" type="revolute">
        <origin rpy="-1.5707963267948966 0 0" xyz="-0.0825 0.384 0" />
        <parent link="fr3_link4" />
        <child link="fr3_link5" />
        <axis xyz="0 0 1" />
        <limit effort="12.0" lower="-2.48" upper="2.48" velocity="3.0" />
        <safety_controller k_position="100.0" k_velocity="40.0" soft_lower_limit="-2.48" soft_upper_limit="2.48" />
        <dynamics D="1" K="7000" damping="0.003" friction="0.0" mu_coulomb="0" mu_viscous="16" />
    </joint>
    <!-- sub-link defining detailed meshes for collision with environment -->
    <link name="fr3_link6">
        <visual>
            <geometry>
                <mesh filename="package://franka_description/meshes/visual/link6.dae" />
            </geometry>
        </visual>
        <collision>
            <geometry>
                <mesh filename="package://franka_description/meshes/collision/link6.stl" />
            </geometry>
        </collision>
        <inertial>
            <origin rpy="0 0 0" xyz="6.0149e-02 -1.4117e-02 -1.0517e-02" />
            <mass value="1.666555" />
            <inertia ixx="0.001964" ixy="0.000109" ixz="-0.001158" iyy="0.004354" iyz="0.000341" izz="0.005433" />
        </inertial>
    </link>
    <!-- sub-link defining coarse geometries of real robot's internal self-collision -->
    <link name="fr3_link6_sc" />
    <!-- fixed joint between both sub-links -->
    <joint name="fr3_link6_sc_joint" type="fixed">
        <origin rpy="0 0 0" />
        <parent link="fr3_link6" />
        <child link="fr3_link6_sc" />
    </joint>
    <joint name="fr3_joint6" type="revolute">
        <origin rpy="1.5707963267948966 0 0" xyz="0 0 0" />
        <parent link="fr3_link5" />
        <child link="fr3_link6" />
        <axis xyz="0 0 1" />
        <limit effort="12.0" lower="0.8521" upper="4.2094" velocity="1.5" />
        <safety_controller k_position="100.0" k_velocity="40.0" soft_lower_limit="0.8521" soft_upper_limit="4.2094" />
        <dynamics D="1" K="7000" damping="0.003" friction="0.0" mu_coulomb="0" mu_viscous="16" />
    </joint>
    <!-- sub-link defining detailed meshes for collision with environment -->
    <link name="fr3_link7">
        <visual>
            <geometry>
                <mesh filename="package://franka_description/meshes/visual/link7.dae" />
            </geometry>
        </visual>
        <collision>
            <geometry>
                <mesh filename="package://franka_description/meshes/collision/link7.stl" />
            </geometry>
        </collision>
        <inertial>
            <origin rpy="0 0 0" xyz="1.0517e-02 -4.252e-03 6.1597e-02" />
            <mass value="0.735522" />
            <inertia ixx="0.012516" ixy="-0.000428" ixz="-0.001196" iyy="0.010027" iyz="-0.000741" izz="0.004815" />
        </inertial>
    </link>
    <!-- sub-link defining coarse geometries of real robot's internal self-collision -->
    <link name="fr3_link7_sc" />
    <!-- fixed joint between both sub-links -->
    <joint name="fr3_link7_sc_joint" type="fixed">
        <origin rpy="0 0 0.7853981633974483" />
        <parent link="fr3_link7" />
        <child link="fr3_link7_sc" />
    </joint>
    <joint name="fr3_joint7" type="revolute">
        <origin rpy="1.5707963267948966 0 0" xyz="0.088 0 0" />
        <parent link="fr3_link6" />
        <child link="fr3_link7" />
        <axis xyz="0 0 1" />
        <limit effort="12.0" lower="-2.6895" upper="2.6895" velocity="3.0" />
        <safety_controller k_position="100.0" k_velocity="40.0" soft_lower_limit="-2.6895" soft_upper_limit="2.6895" />
        <dynamics D="1" K="7000" damping="0.003" friction="0.0" mu_coulomb="0" mu_viscous="16" />
    </joint>
    <link name="fr3_link8" />
    <joint name="fr3_joint8" type="fixed">
        <origin rpy="0 0 0" xyz="0 0 0.107" />
        <parent link="fr3_link7" />
        <child link="fr3_link8" />
    </joint>
    <joint name="fr3_hand_joint" type="fixed">
        <parent link="fr3_link8" />
        <child link="fr3_hand" />
        <origin rpy="0 0 -0.7853981633974483" xyz="0 0 0" />
    </joint>
    <!-- sub-link defining detailed meshes for collision with environment -->
    <link name="fr3_hand">
        <visual>
            <geometry>
                <mesh filename="package://franka_description/meshes/visual/hand.dae" />
            </geometry>
        </visual>
        <collision>
            <geometry>
                <mesh filename="package://franka_description/meshes/collision/hand.stl" />
            </geometry>
        </collision>
        <inertial>
            <origin rpy="0 0 0" xyz="-0.01 0 0.03" />
            <mass value="0.73" />
            <inertia ixx="0.001" ixy="0" ixz="0" iyy="0.0025" iyz="0" izz="0.0017" />
        </inertial>
    </link>
    <!-- sub-link defining coarse geometries of real robot's internal self-collision -->
    <link name="fr3_hand_sc" />
    <!-- fixed joint between both sub-links -->
    <joint name="fr3_hand_sc_joint" type="fixed">
        <origin rpy="0 0 0" />
        <parent link="fr3_hand" />
        <child link="fr3_hand_sc" />
    </joint>
    <!-- Define the hand_tcp frame -->
    <link name="fr3_hand_tcp" />
    <joint name="fr3_hand_tcp_joint" type="fixed">
        <origin rpy="0 0 0" xyz="0 0 0.1034" />
        <parent link="fr3_hand" />
        <child link="fr3_hand_tcp" />
    </joint>
    <link name="fr3_leftfinger">
        <visual>
            <geometry>
                <mesh filename="package://franka_description/meshes/visual/finger.dae" />
            </geometry>
        </visual>
        <!-- screw mount -->
        <collision>
            <origin rpy="0 0 0" xyz="0 18.5e-3 11e-3" />
            <geometry>
                <box size="22e-3 15e-3 20e-3" />
            </geometry>
        </collision>
        <!-- cartriage sledge -->
        <collision>
            <origin rpy="0 0 0" xyz="0 6.8e-3 2.2e-3" />
            <geometry>
                <box size="22e-3 8.8e-3 3.8e-3" />
            </geometry>
        </collision>
        <!-- diagonal finger -->
        <collision>
            <origin rpy="0.5235987755982988 0 0" xyz="0 15.9e-3 28.35e-3" />
            <geometry>
                <box size="17.5e-3 7e-3 23.5e-3" />
            </geometry>
        </collision>
        <!-- rubber tip with which to grasp -->
        <collision>
            <origin rpy="0 0 0" xyz="0 7.58e-3 45.25e-3" />
            <geometry>
                <box size="17.5e-3 15.2e-3 18.5e-3" />
            </geometry>
        </collision>
        <inertial>
            <origin rpy="0 0 0" xyz="0 0 0" />
            <mass value="0.015" />
            <inertia ixx="2.3749999999999997e-06" ixy="0" ixz="0" iyy="2.3749999999999997e-06" iyz="0" izz="7.5e-07" />
        </inertial>
    </link>
    <link name="fr3_rightfinger">
        <visual>
            <origin rpy="0 0 3.141592653589793" xyz="0 0 0" />
            <geometry>
                <mesh filename="package://franka_description/meshes/visual/finger.dae" />
            </geometry>
        </visual>
        <!-- screw mount -->
        <collision>
            <origin rpy="0 0 0" xyz="0 -18.5e-3 11e-3" />
            <geometry>
                <box size="22e-3 15e-3 20e-3" />
            </geometry>
        </collision>
        <!-- cartriage sledge -->
        <collision>
            <origin rpy="0 0 0" xyz="0 -6.8e-3 2.2e-3" />
            <geometry>
                <box size="22e-3 8.8e-3 3.8e-3" />
            </geometry>
        </collision>
        <!-- diagonal finger -->
        <collision>
            <origin rpy="-0.5235987755982988 0 0" xyz="0 -15.9e-3 28.35e-3" />
            <geometry>
                <box size="17.5e-3 7e-3 23.5e-3" />
            </geometry>
        </collision>
        <!-- rubber tip with which to grasp -->
        <collision>
            <origin rpy="0 0 0" xyz="0 -7.58e-3 45.25e-3" />
            <geometry>
                <box size="17.5e-3 15.2e-3 18.5e-3" />
            </geometry>
        </collision>
        <inertial>
            <origin rpy="0 0 0" xyz="0 0 0" />
            <mass value="0.015" />
            <inertia ixx="2.3749999999999997e-06" ixy="0" ixz="0" iyy="2.3749999999999997e-06" iyz="0" izz="7.5e-07" />
        </inertial>
    </link>
    <joint name="fr3_finger_joint1" type="prismatic">
        <parent link="fr3_hand" />
        <child link="fr3_leftfinger" />
        <origin rpy="0 0 0" xyz="0 0 0.0584" />
        <axis xyz="0 1 0" />
        <limit effort="100" lower="0.0" upper="0.04" velocity="0.2" />
        <dynamics damping="0.3" />
    </joint>
    <joint name="fr3_finger_joint2" type="prismatic">
        <parent link="fr3_hand" />
        <child link="fr3_rightfinger" />
        <origin rpy="0 0 0" xyz="0 0 0.0584" />
        <axis xyz="0 -1 0" />
        <limit effort="100" lower="0.0" upper="0.04" velocity="0.2" />
        <mimic joint="fr3_finger_joint1" />
        <dynamics damping="0.3" />
    </joint>
    <joint name="mid_mount_franka_joint" type="fixed">
        <origin rpy="0 0 0" xyz="0.21 0 0.0" />
        <parent link="mid_mount" />
        <child link="fr3_link0" />
    </joint>
    <gazebo reference="fr3_joint1">
        <!-- Needed for ODE to output external wrenches on joints -->
        <provideFeedback>true</provideFeedback>
    </gazebo>
    <transmission name="fr3_joint1_transmission">
        <type>transmission_interface/SimpleTransmission</type>
        <joint name="fr3_joint1">
            <hardwareInterface>hardware_interface/PositionJointInterface</hardwareInterface>
        </joint>
        <actuator name="fr3_joint1_motor">
            <hardwareInterface>hardware_interface/PositionJointInterface</hardwareInterface>
        </actuator>
    </transmission>
    <gazebo reference="fr3_joint2">
        <!-- Needed for ODE to output external wrenches on joints -->
        <provideFeedback>true</provideFeedback>
    </gazebo>
    <transmission name="fr3_joint2_transmission">
        <type>transmission_interface/SimpleTransmission</type>
        <joint name="fr3_joint2">
            <hardwareInterface>hardware_interface/PositionJointInterface</hardwareInterface>
        </joint>
        <actuator name="fr3_joint2_motor">
            <hardwareInterface>hardware_interface/PositionJointInterface</hardwareInterface>
        </actuator>
    </transmission>
    <gazebo reference="fr3_joint3">
        <!-- Needed for ODE to output external wrenches on joints -->
        <provideFeedback>true</provideFeedback>
    </gazebo>
    <transmission name="fr3_joint3_transmission">
        <type>transmission_interface/SimpleTransmission</type>
        <joint name="fr3_joint3">
            <hardwareInterface>hardware_interface/PositionJointInterface</hardwareInterface>
        </joint>
        <actuator name="fr3_joint3_motor">
            <hardwareInterface>hardware_interface/PositionJointInterface</hardwareInterface>
        </actuator>
    </transmission>
    <gazebo reference="fr3_joint4">
        <!-- Needed for ODE to output external wrenches on joints -->
        <provideFeedback>true</provideFeedback>
    </gazebo>
    <transmission name="fr3_joint4_transmission">
        <type>transmission_interface/SimpleTransmission</type>
        <joint name="fr3_joint4">
            <hardwareInterface>hardware_interface/PositionJointInterface</hardwareInterface>
        </joint>
        <actuator name="fr3_joint4_motor">
            <hardwareInterface>hardware_interface/PositionJointInterface</hardwareInterface>
        </actuator>
    </transmission>
    <gazebo reference="fr3_joint5">
        <!-- Needed for ODE to output external wrenches on joints -->
        <provideFeedback>true</provideFeedback>
    </gazebo>
    <transmission name="fr3_joint5_transmission">
        <type>transmission_interface/SimpleTransmission</type>
        <joint name="fr3_joint5">
            <hardwareInterface>hardware_interface/PositionJointInterface</hardwareInterface>
        </joint>
        <actuator name="fr3_joint5_motor">
            <hardwareInterface>hardware_interface/PositionJointInterface</hardwareInterface>
        </actuator>
    </transmission>
    <gazebo reference="fr3_joint6">
        <!-- Needed for ODE to output external wrenches on joints -->
        <provideFeedback>true</provideFeedback>
    </gazebo>
    <transmission name="fr3_joint6_transmission">
        <type>transmission_interface/SimpleTransmission</type>
        <joint name="fr3_joint6">
            <hardwareInterface>hardware_interface/PositionJointInterface</hardwareInterface>
        </joint>
        <actuator name="fr3_joint6_motor">
            <hardwareInterface>hardware_interface/PositionJointInterface</hardwareInterface>
        </actuator>
    </transmission>
    <gazebo reference="fr3_joint7">
        <!-- Needed for ODE to output external wrenches on joints -->
        <provideFeedback>true</provideFeedback>
    </gazebo>
    <transmission name="fr3_joint7_transmission">
        <type>transmission_interface/SimpleTransmission</type>
        <joint name="fr3_joint7">
            <hardwareInterface>hardware_interface/PositionJointInterface</hardwareInterface>
        </joint>
        <actuator name="fr3_joint7_motor">
            <hardwareInterface>hardware_interface/PositionJointInterface</hardwareInterface>
        </actuator>
    </transmission>
    <gazebo reference="fr3_joint1">
        <!-- Needed for ODE to output external wrenches on joints -->
        <provideFeedback>true</provideFeedback>
    </gazebo>
    <transmission name="fr3_joint1_transmission">
        <type>transmission_interface/SimpleTransmission</type>
        <joint name="fr3_joint1">
            <hardwareInterface>hardware_interface/VelocityJointInterface</hardwareInterface>
        </joint>
        <actuator name="fr3_joint1_motor">
            <hardwareInterface>hardware_interface/VelocityJointInterface</hardwareInterface>
        </actuator>
    </transmission>
    <gazebo reference="fr3_joint2">
        <!-- Needed for ODE to output external wrenches on joints -->
        <provideFeedback>true</provideFeedback>
    </gazebo>
    <transmission name="fr3_joint2_transmission">
        <type>transmission_interface/SimpleTransmission</type>
        <joint name="fr3_joint2">
            <hardwareInterface>hardware_interface/VelocityJointInterface</hardwareInterface>
        </joint>
        <actuator name="fr3_joint2_motor">
            <hardwareInterface>hardware_interface/VelocityJointInterface</hardwareInterface>
        </actuator>
    </transmission>
    <gazebo reference="fr3_joint3">
        <!-- Needed for ODE to output external wrenches on joints -->
        <provideFeedback>true</provideFeedback>
    </gazebo>
    <transmission name="fr3_joint3_transmission">
        <type>transmission_interface/SimpleTransmission</type>
        <joint name="fr3_joint3">
            <hardwareInterface>hardware_interface/VelocityJointInterface</hardwareInterface>
        </joint>
        <actuator name="fr3_joint3_motor">
            <hardwareInterface>hardware_interface/VelocityJointInterface</hardwareInterface>
        </actuator>
    </transmission>
    <gazebo reference="fr3_joint4">
        <!-- Needed for ODE to output external wrenches on joints -->
        <provideFeedback>true</provideFeedback>
    </gazebo>
    <transmission name="fr3_joint4_transmission">
        <type>transmission_interface/SimpleTransmission</type>
        <joint name="fr3_joint4">
            <hardwareInterface>hardware_interface/VelocityJointInterface</hardwareInterface>
        </joint>
        <actuator name="fr3_joint4_motor">
            <hardwareInterface>hardware_interface/VelocityJointInterface</hardwareInterface>
        </actuator>
    </transmission>
    <gazebo reference="fr3_joint5">
        <!-- Needed for ODE to output external wrenches on joints -->
        <provideFeedback>true</provideFeedback>
    </gazebo>
    <transmission name="fr3_joint5_transmission">
        <type>transmission_interface/SimpleTransmission</type>
        <joint name="fr3_joint5">
            <hardwareInterface>hardware_interface/VelocityJointInterface</hardwareInterface>
        </joint>
        <actuator name="fr3_joint5_motor">
            <hardwareInterface>hardware_interface/VelocityJointInterface</hardwareInterface>
        </actuator>
    </transmission>
    <gazebo reference="fr3_joint6">
        <!-- Needed for ODE to output external wrenches on joints -->
        <provideFeedback>true</provideFeedback>
    </gazebo>
    <transmission name="fr3_joint6_transmission">
        <type>transmission_interface/SimpleTransmission</type>
        <joint name="fr3_joint6">
            <hardwareInterface>hardware_interface/VelocityJointInterface</hardwareInterface>
        </joint>
        <actuator name="fr3_joint6_motor">
            <hardwareInterface>hardware_interface/VelocityJointInterface</hardwareInterface>
        </actuator>
    </transmission>
    <gazebo reference="fr3_joint7">
        <!-- Needed for ODE to output external wrenches on joints -->
        <provideFeedback>true</provideFeedback>
    </gazebo>
    <transmission name="fr3_joint7_transmission">
        <type>transmission_interface/SimpleTransmission</type>
        <joint name="fr3_joint7">
            <hardwareInterface>hardware_interface/VelocityJointInterface</hardwareInterface>
        </joint>
        <actuator name="fr3_joint7_motor">
            <hardwareInterface>hardware_interface/VelocityJointInterface</hardwareInterface>
        </actuator>
    </transmission>
    <gazebo reference="fr3_joint1">
        <!-- Needed for ODE to output external wrenches on joints -->
        <provideFeedback>true</provideFeedback>
    </gazebo>
    <transmission name="fr3_joint1_transmission">
        <type>transmission_interface/SimpleTransmission</type>
        <joint name="fr3_joint1">
            <hardwareInterface>hardware_interface/EffortJointInterface</hardwareInterface>
        </joint>
        <actuator name="fr3_joint1_motor">
            <hardwareInterface>hardware_interface/EffortJointInterface</hardwareInterface>
            <mechanicalReduction>1</mechanicalReduction>
        </actuator>
    </transmission>
    <gazebo reference="fr3_joint2">
        <!-- Needed for ODE to output external wrenches on joints -->
        <provideFeedback>true</provideFeedback>
    </gazebo>
    <transmission name="fr3_joint2_transmission">
        <type>transmission_interface/SimpleTransmission</type>
        <joint name="fr3_joint2">
            <hardwareInterface>hardware_interface/EffortJointInterface</hardwareInterface>
        </joint>
        <actuator name="fr3_joint2_motor">
            <hardwareInterface>hardware_interface/EffortJointInterface</hardwareInterface>
            <mechanicalReduction>1</mechanicalReduction>
        </actuator>
    </transmission>
    <gazebo reference="fr3_joint3">
        <!-- Needed for ODE to output external wrenches on joints -->
        <provideFeedback>true</provideFeedback>
    </gazebo>
    <transmission name="fr3_joint3_transmission">
        <type>transmission_interface/SimpleTransmission</type>
        <joint name="fr3_joint3">
            <hardwareInterface>hardware_interface/EffortJointInterface</hardwareInterface>
        </joint>
        <actuator name="fr3_joint3_motor">
            <hardwareInterface>hardware_interface/EffortJointInterface</hardwareInterface>
            <mechanicalReduction>1</mechanicalReduction>
        </actuator>
    </transmission>
    <gazebo reference="fr3_joint4">
        <!-- Needed for ODE to output external wrenches on joints -->
        <provideFeedback>true</provideFeedback>
    </gazebo>
    <transmission name="fr3_joint4_transmission">
        <type>transmission_interface/SimpleTransmission</type>
        <joint name="fr3_joint4">
            <hardwareInterface>hardware_interface/EffortJointInterface</hardwareInterface>
        </joint>
        <actuator name="fr3_joint4_motor">
            <hardwareInterface>hardware_interface/EffortJointInterface</hardwareInterface>
            <mechanicalReduction>1</mechanicalReduction>
        </actuator>
    </transmission>
    <gazebo reference="fr3_joint5">
        <!-- Needed for ODE to output external wrenches on joints -->
        <provideFeedback>true</provideFeedback>
    </gazebo>
    <transmission name="fr3_joint5_transmission">
        <type>transmission_interface/SimpleTransmission</type>
        <joint name="fr3_joint5">
            <hardwareInterface>hardware_interface/EffortJointInterface</hardwareInterface>
        </joint>
        <actuator name="fr3_joint5_motor">
            <hardwareInterface>hardware_interface/EffortJointInterface</hardwareInterface>
            <mechanicalReduction>1</mechanicalReduction>
        </actuator>
    </transmission>
    <gazebo reference="fr3_joint6">
        <!-- Needed for ODE to output external wrenches on joints -->
        <provideFeedback>true</provideFeedback>
    </gazebo>
    <transmission name="fr3_joint6_transmission">
        <type>transmission_interface/SimpleTransmission</type>
        <joint name="fr3_joint6">
            <hardwareInterface>hardware_interface/EffortJointInterface</hardwareInterface>
        </joint>
        <actuator name="fr3_joint6_motor">
            <hardwareInterface>hardware_interface/EffortJointInterface</hardwareInterface>
            <mechanicalReduction>1</mechanicalReduction>
        </actuator>
    </transmission>
    <gazebo reference="fr3_joint7">
        <!-- Needed for ODE to output external wrenches on joints -->
        <provideFeedback>true</provideFeedback>
    </gazebo>
    <transmission name="fr3_joint7_transmission">
        <type>transmission_interface/SimpleTransmission</type>
        <joint name="fr3_joint7">
            <hardwareInterface>hardware_interface/EffortJointInterface</hardwareInterface>
        </joint>
        <actuator name="fr3_joint7_motor">
            <hardwareInterface>hardware_interface/EffortJointInterface</hardwareInterface>
            <mechanicalReduction>1</mechanicalReduction>
        </actuator>
    </transmission>
    <transmission name="fr3_franka_state">
        <type>franka_hw/FrankaStateInterface</type>
        <joint name="fr3_joint1">
            <hardwareInterface>franka_hw/FrankaStateInterface</hardwareInterface>
        </joint>
        <joint name="fr3_joint2">
            <hardwareInterface>franka_hw/FrankaStateInterface</hardwareInterface>
        </joint>
        <joint name="fr3_joint3">
            <hardwareInterface>franka_hw/FrankaStateInterface</hardwareInterface>
        </joint>
        <joint name="fr3_joint4">
            <hardwareInterface>franka_hw/FrankaStateInterface</hardwareInterface>
        </joint>
        <joint name="fr3_joint5">
            <hardwareInterface>franka_hw/FrankaStateInterface</hardwareInterface>
        </joint>
        <joint name="fr3_joint6">
            <hardwareInterface>franka_hw/FrankaStateInterface</hardwareInterface>
        </joint>
        <joint name="fr3_joint7">
            <hardwareInterface>franka_hw/FrankaStateInterface</hardwareInterface>
        </joint>
        <actuator name="fr3_motor1">
            <hardwareInterface>franka_hw/FrankaStateInterface</hardwareInterface>
        </actuator>
        <actuator name="fr3_motor2">
            <hardwareInterface>franka_hw/FrankaStateInterface</hardwareInterface>
        </actuator>
        <actuator name="fr3_motor3">
            <hardwareInterface>franka_hw/FrankaStateInterface</hardwareInterface>
        </actuator>
        <actuator name="fr3_motor4">
            <hardwareInterface>franka_hw/FrankaStateInterface</hardwareInterface>
        </actuator>
        <actuator name="fr3_motor5">
            <hardwareInterface>franka_hw/FrankaStateInterface</hardwareInterface>
        </actuator>
        <actuator name="fr3_motor6">
            <hardwareInterface>franka_hw/FrankaStateInterface</hardwareInterface>
        </actuator>
        <actuator name="fr3_motor7">
            <hardwareInterface>franka_hw/FrankaStateInterface</hardwareInterface>
        </actuator>
    </transmission>
    <transmission name="fr3_franka_model">
        <type>franka_hw/FrankaModelInterface</type>
        <joint name="fr3_joint1">
            <role>root</role>
            <hardwareInterface>franka_hw/FrankaModelInterface</hardwareInterface>
        </joint>
        <joint name="fr3_joint8">
            <role>tip</role>
            <hardwareInterface>franka_hw/FrankaModelInterface</hardwareInterface>
        </joint>
        <actuator name="fr3_joint1_motor_root">
            <hardwareInterface>franka_hw/FrankaModelInterface</hardwareInterface>
        </actuator>
        <actuator name="fr3_joint8_motor_tip">
            <hardwareInterface>franka_hw/FrankaModelInterface</hardwareInterface>
        </actuator>
    </transmission>
    <gazebo reference="fr3_finger_joint1">
        <!-- Needed for ODE to output external wrenches on joints -->
        <provideFeedback>true</provideFeedback>
    </gazebo>
    <transmission name="fr3_finger_joint1_transmission">
        <type>transmission_interface/SimpleTransmission</type>
        <joint name="fr3_finger_joint1">
            <hardwareInterface>hardware_interface/EffortJointInterface</hardwareInterface>
        </joint>
        <actuator name="fr3_finger_joint1_motor">
            <hardwareInterface>hardware_interface/EffortJointInterface</hardwareInterface>
            <mechanicalReduction>1</mechanicalReduction>
        </actuator>
    </transmission>
    <gazebo reference="fr3_finger_joint2">
        <!-- Needed for ODE to output external wrenches on joints -->
        <provideFeedback>true</provideFeedback>
    </gazebo>
    <transmission name="fr3_finger_joint2_transmission">
        <type>transmission_interface/SimpleTransmission</type>
        <joint name="fr3_finger_joint2">
            <hardwareInterface>hardware_interface/EffortJointInterface</hardwareInterface>
        </joint>
        <actuator name="fr3_finger_joint2_motor">
            <hardwareInterface>hardware_interface/EffortJointInterface</hardwareInterface>
            <mechanicalReduction>1</mechanicalReduction>
        </actuator>
    </transmission>
    <gazebo reference="fr3_leftfinger">
        <collision>
            <max_contacts>10</max_contacts>
            <surface>
                <contact>
                    <ode>
                        <!-- These two parameter need application specific tuning. -->
                        <!-- Usually you want no "snap out" velocity and a generous -->
                        <!-- penetration depth to keep the grasping stable -->
                        <max_vel>0</max_vel>
                        <min_depth>0.001</min_depth>
                    </ode>
                </contact>
                <friction>
                    <ode>
                        <mu>1.13</mu>
                        <mu2>1.13</mu2>
                    </ode>
                </friction>
                <bounce />
            </surface>
        </collision>
    </gazebo>
    <gazebo reference="fr3_rightfinger">
        <collision>
            <max_contacts>10</max_contacts>
            <surface>
                <contact>
                    <ode>
                        <!-- These two parameter need application specific tuning. -->
                        <!-- Usually you want no "snap out" velocity and a generous -->
                        <!-- penetration depth to keep the grasping stable -->
                        <max_vel>0</max_vel>
                        <min_depth>0.001</min_depth>
                    </ode>
                </contact>
                <friction>
                    <ode>
                        <mu>1.13</mu>
                        <mu2>1.13</mu2>
                    </ode>
                </friction>
                <bounce />
            </surface>
        </collision>
    </gazebo>
    <gazebo>
        <plugin filename="libgazebo_ros_control.so" name="gazebo_ros_control">
            <controlPeriod>0.001</controlPeriod>
            <robotSimType>franka_gazebo/FrankaHWSim</robotSimType>
        </plugin>
        <self_collide>true</self_collide>
    </gazebo>
    <link name="front_realsense" />
    <!--
    The gazebo plugin aligns the depth data with the Z axis, with X=left and Y=up
    ROS expects the depth data along the X axis, with Y=left and Z=up
    This link only exists to give the gazebo plugin the correctly-oriented frame
  -->
    <link name="front_realsense_gazebo" />
    <joint name="front_realsense_gazebo_joint" type="fixed">
        <parent link="front_realsense" />
        <child link="front_realsense_gazebo" />
        <origin rpy="-1.5707963267948966 0 -1.5707963267948966" xyz="0.0 0 0" />
    </joint>
    <gazebo reference="front_realsense">
        <turnGravityOff>true</turnGravityOff>
        <sensor name="front_realsense_depth" type="depth">
            <update_rate>30</update_rate>
            <camera>
                <!-- 75x65 degree FOV for the depth sensor -->
                <horizontal_fov>1.5184351666666667</horizontal_fov>
                <vertical_fov>1.0122901111111111</vertical_fov>
                <image>
                    <width>640</width>
                    <height>480</height>
                    <format>RGB8</format>
                </image>
                <clip>
                    <!-- give the color sensor a maximum range of 50m so that the simulation renders nicely -->
                    <near>0.01</near>
                    <far>50.0</far>
                </clip>
            </camera>
            <plugin filename="libgazebo_ros_openni_kinect.so" name="kinect_controller">
                <baseline>0.2</baseline>
                <alwaysOn>true</alwaysOn>
                <updateRate>30</updateRate>
                <cameraName>realsense</cameraName>
                <imageTopicName>color/image_raw</imageTopicName>
                <cameraInfoTopicName>color/camera_info</cameraInfoTopicName>
                <depthImageTopicName>depth/image_rect_raw</depthImageTopicName>
                <depthImageInfoTopicName>depth/camera_info</depthImageInfoTopicName>
                <pointCloudTopicName>depth/color/points</pointCloudTopicName>
                <frameName>front_realsense_gazebo</frameName>
                <pointCloudCutoff>0.105</pointCloudCutoff>
                <pointCloudCutoffMax>8.0</pointCloudCutoffMax>
                <distortionK1>0.00000001</distortionK1>
                <distortionK2>0.00000001</distortionK2>
                <distortionK3>0.00000001</distortionK3>
                <distortionT1>0.00000001</distortionT1>
                <distortionT2>0.00000001</distortionT2>
                <CxPrime>0</CxPrime>
                <Cx>0</Cx>
                <Cy>0</Cy>
                <focalLength>0</focalLength>
                <hackBaseline>0</hackBaseline>
            </plugin>
        </sensor>
    </gazebo>
    <link name="front_realsense_lens">
        <visual>
            <origin rpy="1.5707963267948966 0 1.5707963267948966" xyz="0.02 0 0" />
            <geometry>
                <mesh filename="package://realsense2_description/meshes/d435.dae" />
            </geometry>
            <material name="white" />
        </visual>
    </link>
    <joint name="front_realsense_lens_joint" type="fixed">
        <!-- Offset the camera 45cm forwards and 1cm up -->
        <origin rpy="-2.0153218 -1.5602106 -1.9209715" xyz="0.02331829590230782 -0.030862982306747333 0.05281234637360323" />
        <parent link="fr3_link8" />
        <child link="front_realsense_lens" />
    </joint>
    <joint name="front_realsense_joint" type="fixed">
        <origin rpy="0 0 0" xyz="0.025 0 0" />
        <parent link="front_realsense_lens" />
        <child link="front_realsense" />
    </joint>
    <gazebo>
        <plugin filename="libgazebo_ros_joint_state_publisher.so" name="joint_state_publisher">
            <jointName>fr3_joint1, fr3_joint2, fr3_joint3, fr3_joint4, fr3_joint5, fr3_joint6, fr3_joint7, fr3_finger_joint1, fr3_finger_joint2, front_left_wheel, front_right_wheel, rear_left_wheel, rear_right_wheel</jointName>
        </plugin>
    </gazebo>
    <transmission name="trans_front_rocker">
        <type>transmission_interface/SimpleTransmission</type>
        <joint name="front_rocker">
            <hardwareInterface>hardware_interface/EffortJointInterface</hardwareInterface>
        </joint>
        <actuator name="front_rocker_motor">
            <hardwareInterface>hardware_interface/EffortJointInterface</hardwareInterface>
            <mechanicalReduction>1</mechanicalReduction>
        </actuator>
    </transmission>
</robot>

